Workbook

Sheet 00_ReadMe
A1: FirstRand Limited — 5-Year Banking Performance & ROE Sustainability Model (FY2020–FY2024)
A4: Model Objective
A6: This model analyzes FirstRand Limited’s historical financial performance over FY2020–FY2024 to assess operating efficiency, profitability drivers, capital strength, and the sustainability of Return on Equity (ROE) through a full credit cycle.
A9: Model Structure
A11: Sheet | B11: Purpose
A12: 01_SourceMap | B12: Traceability log of all financial data
A13: 02_RawFS | B13: 5-year financial data extracted from FY2024 AFS
A14: 03_KPI_Cal | B14: Recalculated KPIs and growth metrics
A15: 04_Trends | B15: Visual cycle analysis
A16: 05_ROE_DuPont | B16: ROE decomposition (ROA × Leverage)
A17: 06_Dashboard | B17: Executive summary view
A18: 07_Notes | B18: Analytical conclusions
A21: Data Source
A23: All financial data sourced from FirstRand Limited FY2024 Annual Financial Statements — Five-Year Review section (A5–A7).
A26: Key Definitions
A28: ROE = Headline earnings / Average ordinary equity ROA = Headline earnings / Average total assets Leverage = Total assets / Total equity CAGR formula used: ((Final / Initial)^(1/4)) – 1
A31: Limitations
A33: The analysis relies on summary five-year data from the FY2024 Annual Financial Statements and does not incorporate quarterly performance, forward guidance, or macroeconomic forecasting.

Sheet 01_SourceMap
A1: All metrics sourced from FY2024 Annual Financial Statements – Five-Year Review table unless otherwise stated.
A3: Metric | B3: Statement | C3: Year | D3: Page | E3: Source Section | F3: RawFS Cell | G3: Adjustment | H3: Comments
A4: Net interest income | B4: IS | C4: FY2024 | D4: FY2024 AFS – Five-Year Review (A5–A7) | E4: Five-Year Review Table | F4: 02_RawFS!B6:F6 | G4: None | H4: Before impairments
A5: Non-interest revenue | B5: IS | C5: FY2024 | D5: FY2024 AFS – Five-Year Review (A5–A7) | E5: Five-Year Review Table | F5: 02_RawFS!B7:F7
A6: Operating expenses | B6: IS | C6: FY2024 | D6: FY2024 AFS – Five-Year Review (A5–A7) | E6: Five-Year Review Table | F6: 02_RawFS!B8:F8
A7: Credit impairment charge | B7: IS | C7: FY2024 | D7: FY2024 AFS – Five-Year Review (A5–A7) | E7: Five-Year Review Table | F7: 02_RawFS!B9:F9 | H7: Stored as positive
A8: Headline earnings | B8: IS | C8: FY2024 | D8: FY2024 AFS – Five-Year Review (A5–A7) | E8: Five-Year Review Table | F8: 02_RawFS!B10:F10
A9: Dividends declared | B9: IS | C9: FY2024 | D9: FY2024 AFS – Five-Year Review (A5–A7) | E9: Five-Year Review Table | F9: 02_RawFS!B11:F11
A11: Total assets | B11: BS | C11: FY2024 | D11: FY2024 AFS – Five-Year Review (A5–A7) | E11: Five-Year Review Table | F11: 02_RawFS!B16:F16
A12: Average total assets | B12: BS | C12: FY2024 | D12: FY2024 AFS – Five-Year Review (A5–A7) | E12: Five-Year Review Table | F12: 02_RawFS!B17:F17
A13: Gross loans / core lending advances | B13: BS | C13: FY2024 | D13: FY2024 AFS – Five-Year Review (A5–A7) | E13: Five-Year Review Table | F13: 02_RawFS!B18:F18
A14: Average loans | B14: BS | C14: FY2024 | D14: FY2024 AFS – Five-Year Review (A5–A7) | E14: Five-Year Review Table | F14: 02_RawFS!B19:F19
A15: Deposits | B15: BS | C15: FY2024 | D15: FY2024 AFS – Five-Year Review (A5–A7) | E15: Five-Year Review Table | F15: 02_RawFS!B20:F20
A16: Total ordinary equity | B16: BS | C16: FY2024 | D16: FY2024 AFS – Five-Year Review (A5–A7) | E16: Five-Year Review Table | F16: 02_RawFS!B21:F21
A17: CET1 capital | B17: BS | C17: FY2024 | D17: FY2024 AFS – Five-Year Review (A5–A7) | E17: Five-Year Review Table | F17: 02_RawFS!B22:F22
A19: ROE | B19: Key Ratios | C19: FY2024 | D19: FY2024 AFS – Five-Year Review (A5–A7) | E19: Five-Year Review Table | F19: 02_RawFS!B27:F27
A20: ROA | B20: Key Ratios | C20: FY2024 | D20: FY2024 AFS – Five-Year Review (A5–A7) | E20: Five-Year Review Table | F20: 02_RawFS!B28:F28
A21: Net interest margin (NIM) | B21: Key Ratios | C21: FY2024 | D21: FY2024 AFS – Five-Year Review (A5–A7) | E21: Five-Year Review Table | F21: 02_RawFS!B29:F29
... A24: CET1 ratio | B24: Key Ratios | C24: FY2024 | D24: FY2024 AFS – Five-Year Review (A5–A7) | E24: Five-Year Review Table | F24: 02_RawFS!B32:F32

Sheet 02_RawFS
A3: Income Statement
A5: R million | B5: FY2020 | C5: FY2021 | D5: FY2022 | E5: FY2023 | F5: FY2024
A6: Net Interest Income | B6: 62915 | C6: 66717 | D6: 69704 | E6: 78932 | F6: 83454
A7: Non-interest revenue | B7: 41691 | C7: 45410 | D7: 49870 | E7: 53476 | F7: 56082
A8: Operating expenses | B8: 55276 | C8: 57215 | D8: 60456 | E8: 68600 | F8: 74731
A9: Credit impairments | B9: 24383 | C9: 11748 | D9: 7064 | E9: 8346 | F9: 12555
A10: Headline earnings | B10: 17326 | C10: 27971 | D10: 36680 | E10: 40960 | F10: 38054
A11: Dividends | B11: 8780 | C11: 13922 | D11: 21018 | E11: 23848 | F11: 22368
A13: Balance Sheet
A15: R million | B15: FY2020 | C15: FY2021 | D15: FY2022 | E15: FY2023 | F15: FY2024
A16: Total assets | B16: 1558854 | C16: 1604206 | D16: 1713409 | E16: 1909152 | F16: 2006799
A17: Average assets | B17: 1562832 | C17: 1576530 | D17: 1650008 | E17: 1811280 | F17: 1957975
A18: Gross loans | B18: 1088419 | C18: 1105280 | D18: 1178765 | E18: 1300003 | F18: 1374655
A19: Average loans | B19: 1071700 | C19: 1094449 | D19: 1146213 | E19: 1253504 | F19: 1339326
A20: Deposits | B20: 1206997 | C20: 1255080 | D20: 1331881 | E20: 1467280 | F20: 1552825
A21: Total equity | B21: 137529 | C21: 151494 | D21: 168201 | E21: 190519 | F21: 195272
A22: CET1 capital | B22: 113916 | C22: 123386 | D22: 134447 | E22: 149605 | F22: 154487
A24: Published Ratios
A26: Ratio | B26: FY2020 | C26: FY2021 | D26: FY2022 | E26: FY2023 | F26: FY2024
A27: ROE | B27: 0.13 | C27: 0.186 | D27: 0.207 | E27: 0.212 | F27: 0.202
A28: ROA | B28: 0.0111 | C28: 0.0177 | D28: 0.0222 | E28: 0.0229 | F28: 0.0194
A29: NIM | B29: 0.0402 | C29: 0.0408 | D29: 0.0421 | E29: 0.0453 | F29: 0.0456
A30: Cost-to-income | B30: 0.528 | C30: 0.51 | D30: 0.503 | E30: 0.52 | F30: 0.526
A31: Credit loss ratio | B31: 0.0197 | C31: 0.0108 | D31: 0.0062 | E31: 0.0067 | F31: 0.0081
A32: CET1 ratio | B32: 0.134 | C32: 0.137 | D32: 0.135 | E32: 0.146 | F32: 0.142

Sheet 03_KPI_Cal
A3: Recalculated Metrics
A5: KPI | B5: FY2020 | C5: FY2021 | D5: FY2022 | E5: FY2023 | F5: FY2024
A6: Total operating income | B6: ='02_RawFS'!B6 + '02_RawFS'!B7 -> 104606 | C6: ='02_RawFS'!C6 + '02_RawFS'!C7 -> 112127 | D6: ='02_RawFS'!D6 + '02_RawFS'!D7 -> 119574 | E6: ='02_RawFS'!E6 + '02_RawFS'!E7 -> 132408 | F6: ='02_RawFS'!F6 + '02_RawFS'!F7 -> 139536
A7: Cost-to-income (recalc) | B7: ='02_RawFS'!B8 / ('02_RawFS'!B6 + '02_RawFS'!B7) -> 0.52842093 | C7: ='02_RawFS'!C8 / ('02_RawFS'!C6 + '02_RawFS'!C7) -> 0.51026961 | D7: ='02_RawFS'!D8 / ('02_RawFS'!D6 + '02_RawFS'!D7) -> 0.50559486 | E7: ='02_RawFS'!E8 / ('02_RawFS'!E6 + '02_RawFS'!E7) -> 0.51809558 | F7: ='02_RawFS'!F8 / ('02_RawFS'!F6 + '02_RawFS'!F7) -> 0.53556788
A8: Credit loss ratio (recalc) | B8: ='02_RawFS'!B9 / '02_RawFS'!B19 -> 0.022751703 | C8: ='02_RawFS'!C9 / '02_RawFS'!C19 -> 0.010734169 | D8: ='02_RawFS'!D9 / '02_RawFS'!D19 -> 0.0061629034 | E8: ='02_RawFS'!E9 / '02_RawFS'!E19 -> 0.0066581359 | F8: ='02_RawFS'!F9 / '02_RawFS'!F19 -> 0.009374118
A9: Loan growth YoY | C9: =('02_RawFS'!C18 / '02_RawFS'!B18) - 1 -> 0.015491277 | D9: =('02_RawFS'!D18 / '02_RawFS'!C18) - 1 -> 0.066485415 | E9: =('02_RawFS'!E18 / '02_RawFS'!D18) - 1 -> 0.10285171 | F9: =('02_RawFS'!F18 / '02_RawFS'!E18) - 1 -> 0.057424483
A10: Deposit growth YoY | C10: =('02_RawFS'!C20 / '02_RawFS'!B20) - 1 -> 0.039836884 | D10: =('02_RawFS'!D20 / '02_RawFS'!C20) - 1 -> 0.061192115 | E10: =('02_RawFS'!E20 / '02_RawFS'!D20) - 1 -> 0.10165998 | F10: =('02_RawFS'!F20 / '02_RawFS'!E20) - 1 -> 0.058301756
A11: Earnings growth YoY | C11: =('02_RawFS'!C10 / '02_RawFS'!B10) - 1 -> 0.61439455 | D11: =('02_RawFS'!D10 / '02_RawFS'!C10) - 1 -> 0.31135819 | E11: =('02_RawFS'!E10 / '02_RawFS'!D10) - 1 -> 0.11668484 | F11: =('02_RawFS'!F10 / '02_RawFS'!E10) - 1 -> -0.070947266
A12: Earnings CAGR | F12: =(('02_RawFS'!F10 / '02_RawFS'!B10)^(1/4)) - 1 -> 0.21737815
A13: Loan CAGR | F13: =(('02_RawFS'!F18/'02_RawFS'!B18)^(1/4))-1 -> 0.060106263
A14: Deposit CAGR | F14: =(('02_RawFS'!F20/'02_RawFS'!B20)^(1/4))-1 -> 0.065010969
A16: ROE Analysis
A17: ROE - 5Y Average | F17: =AVERAGE('02_RawFS'!B27:F27) -> 0.1874
A18: ROE - 5Y Std Dev | F18: =_xlfn.STDEV.P('02_RawFS'!B27:F27) -> 0.029997333

Sheet 04_Trends
A1: FirstRand - 5-Year Performance Trends

Sheet 05_ROE_DuPont
A3: Component | B3: FY2020 | C3: FY2021 | D3: FY2022 | E3: FY2023 | F3: FY2025
A4: ROA (Reported) | B4: ='02_RawFS'!B28 -> 0.0111 | C4: ='02_RawFS'!C28 -> 0.0177 | D4: ='02_RawFS'!D28 -> 0.0222 | E4: ='02_RawFS'!E28 -> 0.0229 | F4: ='02_RawFS'!F28 -> 0.0194
A5: Financial Leverage (Assets / Equity) | B5: ='02_RawFS'!B16 / '02_RawFS'!B21 -> 11.334729 | C5: ='02_RawFS'!C16 / '02_RawFS'!C21 -> 10.589238 | D5: ='02_RawFS'!D16 / '02_RawFS'!D21 -> 10.186675 | E5: ='02_RawFS'!E16 / '02_RawFS'!E21 -> 10.020796 | F5: ='02_RawFS'!F16 / '02_RawFS'!F21 -> 10.276942
A6: Implied ROE (ROA x Leverage) | B6: =B4*B5 -> 0.1258155 | C6: =C4*C5 -> 0.18742951 | D6: =D4*D5 -> 0.2261442 | E6: =E4*E5 -> 0.22947622 | F6: =F4*F5 -> 0.19937267
A7: Reported ROE | B7: ='02_RawFS'!B27 -> 0.13 | C7: ='02_RawFS'!C27 -> 0.186 | D7: ='02_RawFS'!D27 -> 0.207 | E7: ='02_RawFS'!E27 -> 0.212 | F7: ='02_RawFS'!F27 -> 0.202
A8: Difference (Implied - Reported) | B8: =B6-B7 -> -0.0041845036 | C8: =C6-C7 -> 0.0014295101 | D8: =D6-D7 -> 0.019144195 | E8: =E6-E7 -> 0.017476224 | F8: =F6-F7 -> -0.002627327

Sheet 06_Dashboard
A1: FirstRand Limited - 5-Year Performance Dashboard (FY2020-FY2024)
A4: Profitability Snapshot
A6: Metric | B6: Value
A7: 5Y Average ROE | B7: ='03_KPI_Cal'!F17 -> 0.1874
A8: ROE Volatility (Std Dev) | B8: ='03_KPI_Cal'!F18 -> 0.029997333
A9: Earnings CAGR (5Y) | B9: ='03_KPI_Cal'!F12 -> 0.21737815
A12: Growth & Funding
A14: Metric | B14: Value
A15: Loan CAGR | B15: ='03_KPI_Cal'!F13 -> 0.060106263
A16: Deposit CAGR | B16: ='03_KPI_Cal'!F14 -> 0.065010969
A17: Loan-to-Deposit Trend | B17: Deposits > Loans
A20: Capital & Risk Profile
A22: Metric | B22: Value
A23: Latest CET1 Ratio | B23: ='02_RawFS'!F32 -> 0.142
A24: Latest CET1 Loss Ratio | B24: ='02_RawFS'!F31 -> 0.0081
A25: Latest Cost-to-Income | B25: ='02_RawFS'!F30 -> 0.526
A26: Latest NIM | B26: ='02_RawFS'!F29 -> 0.0456
A29: Executive Summary
A31: • 5-year average ROE of ~19% with moderate volatility (~3%) • ROE recovery driven by ROA improvement, not leverage expansion • Balanced loan & deposit growth (~6% CAGR) • Strong CET1 capital supports resilience

Sheet 07_Notes
A1: FirstRand Limited – 5-Year Banking Performance & ROE Sustainability Analysis (FY2020–FY2024)
A5: Data Sources
A7: All financial data was extracted from: - FirstRand Limited Integrated Annual Reports (FY2020–FY2024) - FY2024 Five-Year Review section (used for consolidated historical figures) All amounts are presented in R million, unless otherwise stated. Ratios are expressed in percentages.
A10: Scope of Analysis
A12: This model evaluates: - Profitability performance (ROE, ROA, NIM) - Growth dynamics (Loans, Deposits, Earnings CAGR) - Cost efficiency (Cost-to-Income) - Credit quality (Credit Loss Ratio) - Capital strength (CET1 Ratio) - ROE sustainability using a simplified DuPont framework Time horizon analysed: FY2020–FY2024 (5 years)
A15: Key Calculations & Methodology
A17: 🔹 Total Operating Income Defined as: Net Interest Income + Non-Interest Revenue Used for recalculating cost-to-income ratio. 🔹 Cost-to-Income Ratio (Recalculated) Operating Expenses ÷ Total Operating Income Purpose: Validate reported efficiency trends. 🔹 Credit Loss Ratio (Recalculated) Credit Impairment Charge ÷ Average Loans Note: Credit impairments were treated as positive values for ratio clarity. 🔹 CAGR (5-Year) Formula used: CAGR = (Ending Value ÷ Beginning Value)^(1/4) – 1 Applied to: - Earnings - Loans - Deposits 🔹 ROE Stability Analysis Average ROE (5-Year) - Mean of FY2020–FY2024 ROE ROE Volatility - Standard deviation of 5-year ROE (population method) Purpose: Measure earnings consistency and cyclicality. 🔹 Financial Leverage Average Total Assets ÷ Total Ordinary Equity 🔹 Simplified DuPont Identity ROE ≈ ROA × Financial Leverage Used to test whether reported ROE is structurally supported by balance sheet leverage.
A20: Key Observations
A22: 🔹 Profitability - 5-Year Average ROE: ~19% - ROE volatility: Low (~3%), indicating earnings stability. - NIM expanded post-FY2022, supporting improved profitability. - Earnings CAGR (~21.7%) demonstrates strong recovery and growth post-pandemic.
A24: 🔹 Efficiency - Cost-to-income ratio remained within 50–53% range. - Efficiency stable with moderate cyclicality.
A26: 🔹 Credit Quality - Credit loss ratio peaked in FY2020 (COVID impact). - Normalised significantly by FY2022–FY2023. - FY2024 shows mild cyclical uptick.
A28: 🔹 Growth & Funding - Loan CAGR: ~6% - Deposit CAGR: ~6.5% - Deposits consistently exceed loans → healthy funding structure. - Balanced asset-liability growth reduces liquidity stress risk.
... A40: Analysis based solely on published financial statements. - No segment-level decomposition performed. - No macroeconomic stress modelling included. - Simplified DuPont (does not include tax burden or margin decomposition).

Sheet 08_Valuation_ROE_PB_RI_DDM
A3: FirstRand (FSR) - Project 2 Valuation (ROE / P-B / RI / DDM)
A4: Valuation Date: | B4: 46067
A5: Units | B5: ZAR per share
A7: 1) MARKET SNAPSHOT | B7: Base | C7: Bull | D7: Bear | E7: Notes
A8: Share Price (P0) | B8: 95 | C8: 95 | D8: 95 | E8: JSE close 13 Feb 2026
A9: BVPS (Book value/share) | B9: 38.84 | C9: 38.84 | D9: 38.84 | E9: FY2025 Annual Results
A10: DPS (Dividend/Share) | B10: 4.66 | C10: 4.66 | D10: 4.66 | E10: FY2025 total dividend
A11: Current P/B | B11: =B8/B9 -> 2.445932 | C11: =C8/C9 -> 2.445932 | D11: =D8/D9 -> 2.445932 | E11: Market Multiple (Auto)
A13: 2) COST OF EQUITY (CAPM) | B13: Base | C13: Bull | D13: Bear | E13: Notes
A14: Risk-free Rate (Rf) | B14: 0.07965 | C14: 0.075 | D14: 0.085
A15: Equity Risk Premium (ERP) | B15: 0.055 | C15: 0.05 | D15: 0.06
A16: Beta (β) | B16: 1.15 | C16: 1.05 | D16: 1.25
A17: Cost of equity (Ke) | B17: =B14 + (B16 * B15) -> 0.1429 | C17: =C14 + (C16 * C15) -> 0.1275 | D17: =D14 + (D16 * D15) -> 0.16
A19: 3) SUSTAINABLE ROE & GROWTH | B19: Base | C19: Bull | D19: Bear | E19: Notes
A20: Sustainable ROE (ROE_s) | B20: 0.2 | C20: 0.22 | D20: 0.18
A21: Earnings Per Share Implied (EPS0) | B21: =B20 * B9 -> 7.768 | C21: =C20 * C9 -> 8.5448 | D21: =D20 * D9 -> 6.9912
A22: Payout Ratio (p) | B22: =B10 / B21 -> 0.59989701 | C22: =C10 / C21 -> 0.54536092 | D22: =D10 / D21 -> 0.66655224
A23: Retention Ratio (b) | B23: =1-B22 -> 0.40010299 | C23: =1-C22 -> 0.45463908 | D23: =1-D22 -> 0.33344776
A24: Sustainable Growth (g) | B24: =B20 * B23 -> 0.080020597 | C24: =C20 * C23 -> 0.1000206 | D24: =D20 * D23 -> 0.060020597
A26: 4) JUSTIFIED P/B (ROE vs Ke) | B26: Base | C26: Bull | D26: Bear | E26: Notes
A27: Justified P/B | B27: =(B20-B24)/(B17-B24) -> 1.9080875 | C27: =(C20-C24)/(C17-C24) -> 4.3661576 | D27: =(D20-D24)/(D17-D24) -> 1.2000412
A28: Fair Value (P*) | B28: =B27 * B9 -> 74.110119 | C28: =C27 * C9 -> 169.58156 | D28: =D27 * D9 -> 46.6096
A29: Upside/(Downside) | B29: =(B28-B8)/B8 -> -0.21989349 | C29: =(C28-C8)/C8 -> 0.78506906 | D29: =(D28-D8)/D8 -> -0.50937263
A31: 5) MARKET-IMPLIED EXPECTATIONS | B31: Base | C31: Bull | D31: Bear | E31: Notes
A32: Market P/B | B32: =B11 -> 2.445932 | C32: =$B$32 -> 2.445932 | D32: =$B$32 -> 2.445932
A33: Implied ROE (market) | B33: =B24 + (B32*(B17-B24)) -> 0.23381934 | C33: =C24 + (C32 * (C17 - C24)) -> 0.16723335 | D33: =D24 + (D32 * (D17 - D24)) -> 0.30456342
A34: Gap: ROE - Implied | B34: =B20 - B33 -> -0.033819342 | C34: =C20 - C33 -> 0.052766652 | D34: =D20 - D33 -> -0.12456342
A36: 6) RESIDUAL INCOME (RI) - CROSS-CHECK | B36: Base | C36: Bull | D36: Bear | E36: Notes
A37: Excess Return (ROE - Ke) | B37: =B20 - B17 -> 0.0571 | C37: =C20-C17 -> 0.0925 | D37: =D20 - D17 -> 0.02
A38: RI-Justified P/B | B38: =1 + (B37 / (B17 - B24)) -> 1.9080875 | C38: =1 + (C37 / (C17 - C24)) -> 4.3661576 | D38: =1 + (D37 / (D17 - D24)) -> 1.2000412
A39: RI Fair Value | B39: =B38 * B9 -> 74.110119 | C39: =C38 * C9 -> 169.58156 | D39: =D38 * D9 -> 46.6096
A41: 7) DDM - CROSS-CHECK | B41: Base | C41: Bull | D41: Bear | E41: Notes
A42: DPS1 | B42: =B10 * (1 + B24) -> 5.032896 | C42: =C10 * (1 + C24) -> 5.126096 | D42: =D10 * (1 + D24) -> 4.939696
A43: DDM Value | B43: =B42 / (B17 - B24) -> 80.040455 | C43: =C42 / (C17 - C24) -> 186.54321 | D43: =D42 / (D17 - D24) -> 49.407136
A46: 8) SENSITIVITY TABLES | B46: 0.06
A48: ROE \ Ke | B48: 0.13 | C48: 0.14 | D48: 0.15 | E48: 0.16 | F48: 0.17 | G48: 0.18
A49: 0.16 | B49: =(A49-$B$46)/(B48-$B$46) -> 1.4285714 | C49: =(A49-$B$46)/(C48-$B$46) -> 1.25 | D49: =(A49-$C$46)/(D48-$C$46) -> 1.0666667 | E49: =(A49-$C$46)/(E48-$C$46) -> 1 | F49: =(A49-$C$46)/(F48-$C$46) -> 0.94117647 | G49: =(A49-$C$46)/(G48-$C$46) -> 0.88888889
A50: 0.18 | B50: =(A50-$B$46)/(B48-$B$46) -> 1.7142857 | C50: =(A50-$B$46)/(C48-$B$46) -> 1.5 | D50: =(A50-$B$46)/(D48-$B$46) -> 1.3333333 | E50: =(A50-$B$46)/(E48-$B$46) -> 1.2 | F50: =(A50-$B$46)/(F48-$B$46) -> 1.0909091 | G50: =(A50-$B$46)/(G48-$B$46) -> 1
A51: 0.2 | B51: =(A51-$B$46)/(B48-$B$46) -> 2 | C51: =(A51-$B$46)/(C48-$B$46) -> 1.75 | D51: =(A51-$B$46)/(D48-$B$46) -> 1.5555556 | E51: =(A51-$B$46)/(E48-$B$46) -> 1.4 | F51: =(A51-$B$46)/(F48-$B$46) -> 1.2727273 | G51: =(A51-$B$46)/(G48-$B$46) -> 1.1666667
A52: 0.22 | B52: =(A52-$B$46)/(B48-$B$46) -> 2.2857143 | C52: =(A52-$B$46)/(C48-$B$46) -> 2 | D52: =(A52-$B$46)/(D48-$B$46) -> 1.7777778 | E52: =(A52-$B$46)/(E48-$B$46) -> 1.6 | F52: =(A52-$B$46)/(F48-$B$46) -> 1.4545455 | G52: =(A52-$B$46)/(G48-$B$46) -> 1.3333333
...

Sheet 09_Valuation_Report
A3: Project 2 - Banking Valuation Framework
A4: FirstRand Limited
A5: Valuation Date: 14-Feb-2026
A8: Valuation Objective
A10: The objective of this section is to translate the sustainable ROE analysis from Project 1 into a justified valuation framework.
A12: The valuation approach incorporates: - Price-to-Book (P/B) anchored to sustainable ROE - Residual Income (RI) cross-check - Dividend Discount Model (DDM) cross-check - Market-implied expectations analysis - ROE versus Cost of Equity (Ke) sensitivity testing
A14: Core Question: Does the current market valuation fairly reflect sustainable ROE and long-term growth expectations?
A17: Market Snapshot
A19: Current Share Price: R95 Book Value Per Share (BVPS): R38.84 Current Price-to-Book (P/B): 2.45x Dividend per Share (FY2025): R4.66
A21: At 2.45x book value, FirstRand trades at a premium to its equity base. This premium implies sustained value creation above the cost of equity.
A24: Base Case Valuation
A25: (Sustainable ROE: 20% | Cost of Equity: approximately 14%)
... A136: Upside from current levels requires confirmation that ROE above 22% is structurally sustainable rather than cyclically elevated.

Sheet PROJECT 3 - CAPITAL & RISK
A1: Project 3 – Financial Strength & Risk Assessment
A3: Capital adequacy
A4: Credit discipline
A5: Funding structure
A6: Liquidity position
A7: Stress testing framework

Sheet P3_01_Capital
A3: FirstRand – Capital Adequacy & Buffer Analysis
A4: Coverage: FY2020–FY2024
A6: Raw Extracted Data
A8: Metric | B8: FY20 | C8: FY21 | D8: FY22 | E8: FY23 | F8: FY24
A9: CET1 ratio (%) | B9: 0.115 | C9: 0.135 | D9: 0.121 | E9: 0.132 | F9: 0.135
A10: Total capital ratio (%) | B10: 0.145 | C10: 0.163 | D10: 0.149 | E10: 0.156 | F10: 0.161
A11: Risk-weighted assets (RWA) | B11: 1114321 | C11: 1058916 | D11: 1135517 | E11: 1323864 | F11: 1400000
A12: CET1 capital (R) | B12: 121785 | C12: 143000 | D12: 137189 | E12: 174740 | F12: 189158
A13: Regulatory minimum CET1 (%) | B13: 0.07 | C13: 0.08 | D13: 0.08 | E13: 0.088 | F13: 0.09
A14: Management target range (if disclosed) | B14: 11%-12% | C14: 11%-12% | D14: 11%-12% | E14: 11%-12% | F14: 11%-12%
A15: Dividends paid | B15: 16716 | C15: 6170 | D15: 17390 | E15: 27991 | F15: 22158
A16: Headline earnings (R million) | B16: 17326 | C16: 26950 | D16: 32817 | E16: 36700 | F16: 38054
A17: Retained earnings (calc) | B17: =B16-B15 -> 610 | C17: =C16-C15 -> 20780 | D17: =D16-D15 -> 15427 | E17: =E16-E15 -> 8709 | F17: =F16-F15 -> 15896
A19: Derived Metrics (Analytical Layer)
A21: Metric | B21: FY20 | C21: FY21 | D21: FY22 | E21: FY23 | F21: FY24
A22: CET1 buffer (%) | B22: =B9-B13 -> 0.045 | C22: =C9-C13 -> 0.055 | D22: =D9-D13 -> 0.041 | E22: =E9-E13 -> 0.044 | F22: =F9-F13 -> 0.045
A23: RWA growth (%) | C23: -0.0498 | D23: 0.0722 | E23: 0.1659 | F23: 0.0575
A24: CET1 growth (%) | C24: 0.1741 | D24: -0.0406 | E24: 0.2736 | F24: 0.0825
A25: Payout ratio (%) | B25: =B15/B16 -> 0.9647928 | C25: =C15/C16 -> 0.22894249 | D25: =D15/D16 -> 0.52990828 | E25: =E15/E16 -> 0.76269755 | F25: =F15/F16 -> 0.58227782
A26: Capital build (R) | B26: =B17 -> 610 | C26: =C17 -> 20780 | D26: =D17 -> 15427 | E26: =E17 -> 8709 | F26: =F17 -> 15896

Sheet P3_02_Credit
A3: Credit Quality & Provisioning Analysis
A5: Raw Inputs
A7: Metric | B7: FY20 | C7: FY21 | D7: FY22 | E7: FY23 | F7: FY24
A8: Gross loans | B8: 1311095 | C8: 1274052 | D8: 1382058 | E8: 1590447 | F8: 1665706
A9: Stage 3 / NPLs | B9: 57281 | C9: 60705 | D9: 50886 | E9: 57432 | F9: 67840
A10: Performing loans | B10: =B8-B9 -> 1253814 | C10: =C8-C9 -> 1213347 | D10: =D8-D9 -> 1331172 | E10: =E8-E9 -> 1533015 | F10: =F8-F9 -> 1597866
A11: ECL allowance | B11: 49380 | C11: 50618 | D11: 47734 | E11: 51072 | F11: 54165
A12: Impairment charge | B12: 12555 | C12: 13660 | D12: 7080 | E12: 10949 | F12: 12555
A13: Credit loss ratio (%) | B13: 0.0197 | C13: 0.011 | D13: 0.0056 | E13: 0.0078 | F13: 0.0081
A15: Derived Ratios
A17: Metric | B17: FY20 | C17: FY21 | D17: FY22 | E17: FY23 | F17: FY24
A18: Stage 3 ratio (%) | B18: =B9/B8 -> 0.043689435 | C18: =C9/C8 -> 0.047647192 | D18: =D9/D8 -> 0.036819005 | E18: =E9/E8 -> 0.036110603 | F18: =F9/F8 -> 0.040727475
A19: Coverage ratio (%) | B19: =B11/B9 -> 0.86206596 | C19: =C11/C9 -> 0.83383576 | D19: =D11/D9 -> 0.93805762 | E19: =E11/E9 -> 0.88926034 | F19: =F11/F9 -> 0.79842276
A20: Performing loan ratio (%) | B20: =(B8-B9)/B8 -> 0.95631056 | C20: =(C8-C9)/C8 -> 0.95235281 | D20: =(D8-D9)/D8 -> 0.963181 | E20: =(E8-E9)/E8 -> 0.9638894 | F20: =(F8-F9)/F8 -> 0.95927252
A21: Cost of risk trend | B21: 0.0197 | C21: 0.011 | D21: 0.0056 | E21: 0.0078 | F21: 0.0081
A22: Impairment-to-loans (%) | B22: =B12/B8 -> 0.0095759651 | C22: =C12/C8 -> 0.010721697 | D22: =D12/D8 -> 0.0051227951 | E22: =E12/E8 -> 0.0068842281 | F22: =F12/F8 -> 0.0075373445

Sheet P3_03_Funding_Liquidity
A3: Funding Structure & Liquidity Resilience
A6: Metric | B6: FY20 | C6: FY21 | D6: FY22 | E6: FY23 | F6: FY24
A7: Gross loans | B7: 1311095 | C7: 1274052 | D7: 1382058 | E7: 1590447 | F7: 1665706
A8: Customer deposits | B8: 1241226 | C8: 1263451 | D8: 1412975 | E8: 1620458 | F8: 1724773
A9: Total funding liabilities | B9: 1508940 | C9: 1525870 | D9: 1655972 | E9: 1923103 | F9: 2003151
A10: Wholesale funding | B10: 267714 | C10: 262419 | D10: 242997 | E10: 302645 | F10: 278378
A11: Retail deposits | B11: 1241226 | C11: 1263451 | D11: 1412975 | E11: 1620458 | F11: 1724773
A12: LCR (%) | B12: 1.31 | C12: 1.24 | D12: 1.21 | E12: 1.2 | F12: 1.18
A13: NSFR (%) | B13: 1.18 | C13: 1.21 | D13: 1.22 | E13: 1.19 | F13: 1.2
A15: Derived Ratios
A17: Metric | B17: FY20 | C17: FY21 | D17: FY22 | E17: FY23 | F17: FY24
A18: Loan-to-deposit ratio (%) | B18: =B7/B8 -> 1.0562903 | C18: =C7/C8 -> 1.0083905 | D18: =D7/D8 -> 0.97811922 | E18: =E7/E8 -> 0.98147993 | F18: =F7/F8 -> 0.96575375
A19: Deposit growth (%) | C19: =(C8-B8)/B8 -> 0.017905684 | D19: =(D8-C8)/C8 -> 0.11834571 | E19: =(E8-D8)/D8 -> 0.14684124 | F19: =(F8-E8)/E8 -> 0.064373776
A20: Loan growth (%) | C20: =(C7-B7)/B7 -> -0.028253483 | D20: =(D7-C7)/C7 -> 0.08477362 | E20: =(E7-D7)/D7 -> 0.15078166 | F20: =(F7-E7)/E7 -> 0.047319401
A21: Wholesale funding ratio (%) | B21: =B10/B9 -> 0.17741859 | C21: =C10/C9 -> 0.17197992 | D21: =D10/D9 -> 0.1467398 | E21: =E10/E9 -> 0.15737327 | F21: =F10/F9 -> 0.13897005
A22: Liquidity buffer (%) | B22: 0.31 | C22: 0.24 | D22: 0.21 | E22: 0.2 | F22: 0.18

Sheet P3_04_Stress_Test
A3: Stress Assumptions
A5: Variable | B5: Base | C5: Mild | D5: Severe
A6: Credit loss ratio | B6: 0.0081 | C6: 0.012 | D6: 0.018
A7: NIM change | B7: 0bps | C7: -20bps | D7: -50bps
A8: Cost increase | B8: 0 | C8: 0.03 | D8: 0.06
A9: RWA growth | B9: 0.05 | C9: 0.07 | D9: 0.1
A11: Impact on Earnings
A13: Scenario | B13: Earnings | C13: ROE | D13: CET1 buffer
A14: Base | B14: 38054 | C14: 0.179 | D14: 0.045
A15: Mild | B15: 31557 | C15: 0.148 | D15: 0.036
A16: Severe | B16: 21562 | C16: 0.101 | D16: 0.033

Sheet P3_05_Summary
A3: Financial Strength & Risk Summary
A6: Capital Adequacy Assessment
A8: Key Metrics (FY2024)
A10: - CET1 ratio: 13.5%
A11: - Regulatory minimum: 9.0%
A12: - CET1 buffer: 4.5%
A13: - Internal target: 11–12%
A14: Capital build is positive.
A16: Conclusion:
A17: FirstRand maintains a material buffer above regulatory and internal targets.
A18: Capital generation remains strong through-cycle.
A19: Balance sheet is not capital constrained.
... A51: Stress Test Outcome
A54: Scenario | B54: ROE | C54: CET1 Buffer
A55: Base | B55: 17.9% | C55: 4.5%
A56: Mild | B56: 14.8% | C56: 3.6%
A57: Severe | B57: 10.1% | C57: 3.3%
A59: Interpretation:
A60: Even under severe stress:
A62: Capital buffer remains >3%
A63: ROE remains positive
A64: Bank does not breach regulatory capital
A66: This confirms durability.
A69: Overall Risk Assessment: LOW–MODERATE
A71: • Capital strength: Strong
A72: • Credit risk: Normalizing
A73: • Funding risk: Low
A74: • Liquidity risk: Low
A75: • Earnings sensitivity: Manageable
A77: FirstRand can absorb a macro downturn without breaching capital requirements or losing structural profitability.
